2025-04-10 23:34:54,660 INFO: Debug AdGest startup [in C:\Python\AdGest\app\__init__.py:110]
2025-04-10 23:34:57,334 INFO: Debug AdGest startup [in C:\Python\AdGest\app\__init__.py:110]
2025-04-10 23:43:38,466 INFO: Debug AdGest startup [in C:\Python\AdGest\app\__init__.py:110]
2025-04-10 23:43:41,052 INFO: Debug AdGest startup [in C:\Python\AdGest\app\__init__.py:110]
2025-04-10 23:45:54,362 INFO: Debug AdGest startup [in C:\Python\AdGest\app\__init__.py:110]
2025-04-10 23:45:56,844 INFO: Debug AdGest startup [in C:\Python\AdGest\app\__init__.py:110]
2025-04-11 01:18:17,213 INFO: Debug AdGest startup [in C:\Python\AdGest\app\__init__.py:110]
2025-04-11 01:18:18,488 INFO: Debug AdGest startup [in C:\Python\AdGest\app\__init__.py:110]
2025-04-11 12:03:51,244 INFO: Debug AdGest startup [in C:\Python\AdGest\app\__init__.py:110]
2025-04-11 12:03:53,796 INFO: Debug AdGest startup [in C:\Python\AdGest\app\__init__.py:110]
2025-04-11 12:52:37,393 INFO: Campo profile_image está vazio. [in C:\Python\AdGest\app\routes.py:76]
2025-04-11 12:54:00,748 INFO: Tipo de form.profile_image.data: <class 'werkzeug.datastructures.file_storage.FileStorage'> [in C:\Python\AdGest\app\routes.py:62]
2025-04-11 12:54:00,755 INFO: Arquivo recebido: <FileStorage: '9deb08cbac490f5fa43032499f61c581.jpg' ('image/jpeg')> [in C:\Python\AdGest\app\routes.py:65]
2025-04-11 12:54:00,757 INFO: Salvando imagem em: C:\Python\AdGest\app\static\icons\9deb08cbac490f5fa43032499f61c581.jpg [in C:\Python\AdGest\app\routes.py:70]
2025-04-11 20:30:12,290 INFO: Debug AdGest startup [in C:\Python\AdGest\app\__init__.py:110]
2025-04-11 20:30:13,370 INFO: Debug AdGest startup [in C:\Python\AdGest\app\__init__.py:110]
2025-04-23 00:08:41,634 ERROR: Erro ao excluir assunto: list() takes 0 positional arguments but 1 was given [in C:\Python\AdGest - Cópia\app\assuntos\routes.py:207]
2025-04-23 00:12:10,194 ERROR: Erro ao excluir assunto: list() takes 0 positional arguments but 1 was given [in C:\Python\AdGest - Cópia\app\assuntos\routes.py:208]
2025-04-23 00:12:20,019 ERROR: Erro ao excluir assunto: list() takes 0 positional arguments but 1 was given [in C:\Python\AdGest - Cópia\app\assuntos\routes.py:208]
2025-04-27 12:08:00,120 ERROR: Erro ao importar clientes: (sqlite3.IntegrityError) UNIQUE constraint failed: clients.user_id, clients.name
[SQL: UPDATE clients SET name=?, nif=?, email=?, telephone=? WHERE clients.id = ?]
[parameters: ('Garcia', '587469', 'gring@gma', '365875', 4)]
(Background on this error at: https://sqlalche.me/e/20/gkpj) [in C:\Python\AdGest - Cópia\app\clientes\services.py:174]
2025-04-27 12:08:00,122 ERROR: Erro de integridade ao importar clientes: (sqlite3.IntegrityError) UNIQUE constraint failed: clients.user_id, clients.name
[SQL: UPDATE clients SET name=?, nif=?, email=?, telephone=? WHERE clients.id = ?]
[parameters: ('Garcia', '587469', 'gring@gma', '365875', 4)]
(Background on this error at: https://sqlalche.me/e/20/gkpj) [in C:\Python\AdGest - Cópia\app\clientes\routes.py:122]
2025-05-01 12:42:49,550 ERROR: Erro editando prazo: (sqlite3.IntegrityError) NOT NULL constraint failed: prazos_judiciais.stage
[SQL: UPDATE prazos_judiciais SET assunto=?, stage=? WHERE prazos_judiciais.id = ?]
[parameters: ('Prazo novo do Andre e tambem do manel mas é este é o cliente', None, 1)]
(Background on this error at: https://sqlalche.me/e/20/gkpj) [in C:\Python\AdGest - Cópia\app\prazos\routes.py:272]
2025-05-01 12:43:10,500 ERROR: Erro editando prazo: (sqlite3.IntegrityError) NOT NULL constraint failed: prazos_judiciais.stage
[SQL: UPDATE prazos_judiciais SET assunto=?, stage=? WHERE prazos_judiciais.id = ?]
[parameters: ('Prazo novo do Andre e tambem do manel mas é este é o cliente', None, 1)]
(Background on this error at: https://sqlalche.me/e/20/gkpj) [in C:\Python\AdGest - Cópia\app\prazos\routes.py:272]
2025-05-01 12:46:00,588 ERROR: Erro editando prazo: (sqlite3.IntegrityError) CHECK constraint failed: chk_prazos_stage
[SQL: UPDATE prazos_judiciais SET assunto=?, stage=? WHERE prazos_judiciais.id = ?]
[parameters: ('Prazo novo do Andre e tambem do manel mas é este é o cliente', '<PhaseDefinition 1>', 1)]
(Background on this error at: https://sqlalche.me/e/20/gkpj) [in C:\Python\AdGest - Cópia\app\prazos\routes.py:273]
2025-05-01 12:47:22,373 ERROR: Erro editando prazo: (sqlite3.IntegrityError) CHECK constraint failed: chk_prazos_stage
[SQL: UPDATE prazos_judiciais SET assunto=?, stage=? WHERE prazos_judiciais.id = ?]
[parameters: ('Prazo novo do Andre e tambem do manel mas é este é o cliente', '1', 1)]
(Background on this error at: https://sqlalche.me/e/20/gkpj) [in C:\Python\AdGest - Cópia\app\prazos\routes.py:285]
2025-05-01 12:47:29,254 ERROR: Erro editando prazo: (sqlite3.IntegrityError) CHECK constraint failed: chk_prazos_stage
[SQL: UPDATE prazos_judiciais SET assunto=?, stage=? WHERE prazos_judiciais.id = ?]
[parameters: ('Prazo novo do Andre e tambem do manel mas é este é o cliente', '1', 1)]
(Background on this error at: https://sqlalche.me/e/20/gkpj) [in C:\Python\AdGest - Cópia\app\prazos\routes.py:285]
2025-05-01 12:48:05,698 ERROR: Erro editando prazo: (sqlite3.IntegrityError) CHECK constraint failed: chk_prazos_stage
[SQL: UPDATE prazos_judiciais SET stage=? WHERE prazos_judiciais.id = ?]
[parameters: ('1', 1)]
(Background on this error at: https://sqlalche.me/e/20/gkpj) [in C:\Python\AdGest - Cópia\app\prazos\routes.py:285]
2025-05-01 12:48:13,360 ERROR: Erro editando prazo: (sqlite3.IntegrityError) CHECK constraint failed: chk_prazos_stage
[SQL: UPDATE prazos_judiciais SET assunto=?, stage=? WHERE prazos_judiciais.id = ?]
[parameters: ('Prazo novo do Andre e tambem do manel mas é este é o cliente', '1', 1)]
(Background on this error at: https://sqlalche.me/e/20/gkpj) [in C:\Python\AdGest - Cópia\app\prazos\routes.py:285]
2025-05-01 14:42:42,089 ERROR: Erro deletando prazo: (sqlite3.IntegrityError) NOT NULL constraint failed: process_phases.prazo_id
[SQL: UPDATE process_phases SET prazo_id=? WHERE process_phases.id = ?]
[parameters: (None, 1)]
(Background on this error at: https://sqlalche.me/e/20/gkpj) [in C:\Python\AdGest - Cópia\app\prazos\routes.py:353]
2025-05-01 23:34:38,817 ERROR: Erro editando prazo: Object of type date is not JSON serializable [in C:\Python\AdGest - Cópia\app\prazos\routes.py:536]
2025-05-02 23:12:23,675 ERROR: Erro deletando prazo: (sqlite3.IntegrityError) NOT NULL constraint failed: process_phases.prazo_id
[SQL: UPDATE process_phases SET prazo_id=? WHERE process_phases.id = ?]
[parameters: [(None, 2), (None, 4)]]
(Background on this error at: https://sqlalche.me/e/20/gkpj) [in C:\Python\AdGest - Cópia\app\prazos\routes.py:593]
2025-05-18 18:23:47,129 ERROR: Erro ao processar CSV [in C:\Python\AdGest - Cópia\app\accounting\routes.py:159]
Traceback (most recent call last):
  File "C:\Python\AdGest - Cópia\app\accounting\routes.py", line 155, in upload_csv
    tmp = CsvService.save_tmp(rows, current_user)
  File "C:\Python\AdGest - Cópia\app\accounting\services.py", line 194, in save_tmp
    tmp = TmpDocumento(data=rows, user_id=user.id)
  File "<string>", line 4, in __init__
  File "C:\Python\AdGest - Cópia\venv\Lib\site-packages\sqlalchemy\orm\state.py", line 571, in _initialize_instance
    with util.safe_reraise():
         ~~~~~~~~~~~~~~~~~^^
  File "C:\Python\AdGest - Cópia\venv\Lib\site-packages\sqlalchemy\util\langhelpers.py", line 146, in __exit__
    raise exc_value.with_traceback(exc_tb)
  File "C:\Python\AdGest - Cópia\venv\Lib\site-packages\sqlalchemy\orm\state.py", line 569, in _initialize_instance
    manager.original_init(*mixed[1:], **kwargs)
    ~~~~~~~~~~~~~~~~~~~~~^^^^^^^^^^^^^^^^^^^^^^
  File "C:\Python\AdGest - Cópia\venv\Lib\site-packages\sqlalchemy\orm\decl_base.py", line 2178, in _declarative_constructor
    setattr(self, k, kwargs[k])
    ~~~~~~~^^^^^^^^^^^^^^^^^^^^
  File "C:\Python\AdGest - Cópia\venv\Lib\site-packages\sqlalchemy\orm\attributes.py", line 537, in __set__
    self.impl.set(
    ~~~~~~~~~~~~~^
        instance_state(instance), instance_dict(instance), value, None
        ^^^^^^^^^^^^^^^^^^^^^^^^^^^^^^^^^^^^^^^^^^^^^^^^^^^^^^^^^^^^^^
    )
    ^
  File "C:\Python\AdGest - Cópia\venv\Lib\site-packages\sqlalchemy\orm\attributes.py", line 1277, in set
    value = self.fire_replace_event(
        state, dict_, value, old, initiator
    )
  File "C:\Python\AdGest - Cópia\venv\Lib\site-packages\sqlalchemy\orm\attributes.py", line 1292, in fire_replace_event
    value = fn(
        state, value, previous, initiator or self._replace_token
    )
  File "C:\Python\AdGest - Cópia\venv\Lib\site-packages\sqlalchemy\orm\events.py", line 2579, in wrap
    return fn(target, *arg)
  File "C:\Python\AdGest - Cópia\venv\Lib\site-packages\sqlalchemy\ext\mutable.py", line 556, in set_
    value = cls.coerce(key, value)
  File "C:\Python\AdGest - Cópia\venv\Lib\site-packages\sqlalchemy\ext\mutable.py", line 882, in coerce
    return Mutable.coerce(key, value)
           ~~~~~~~~~~~~~~^^^^^^^^^^^^
  File "C:\Python\AdGest - Cópia\venv\Lib\site-packages\sqlalchemy\ext\mutable.py", line 475, in coerce
    raise ValueError(msg % (key, type(value)))
ValueError: Attribute 'data' does not accept objects of type <class 'list'>
2025-05-21 23:18:38,484 ERROR: Erro ao compartilhar cliente: Could not build url for endpoint 'clientes.client_info' with values ['client_id']. Did you mean 'client.client_info' instead? [in C:\Python\AdGest - Cópia\app\clientes\routes.py:188]
